Workbook

Sheet ex2024
A1: UF | B1: Estatal | C1: Sigla | D1: CNPJ | E1: Situação | F1: Setor | G1: Espécie | H1: Organização jurídica | I1: Tipo de Capital | J1: Listada em Bolsa | K1: É Subsidiária | L1: Dependência | M1: Número de Empregados (incluindo temporários e terceirizados) | N1: Possui Conselho de Administração | O1: Possui Conselho Fiscal | P1: Possui Comitê de Autidoria | Q1: Link Carta Anual | R1: Receita Líquida Operacional | S1: Despesa com Pessoal, incluindo temporários e terceirizados (por competência) | T1: Despesa Total (por competência) | U1: Investimento (por competência) | V1: Foi Distribuído PLR ou RVA no exercício | W1: Remuneração bruta total paga no ano (empregado que recebeu a maior remuneração) | X1: PLR ou RVA pagos no ano (empregado que recebeu a maior remuneração) | Y1: Indenizações pagas no ano (empregado que recebeu a maior remuneração) | Z1: Lucro / Prejuízo Líquido do Exercício | AA1: Patrimônio Líquido | AB1: Valor de Mercado | AC1: Dividendos e Juros sobre Capital Próprio pagos ao Tesouro Estadual / Municipal (pago) | AD1: Subvenções - Exercício anterior | AE1: Subvenções - Exercício | AF1: Passivos - Exercício anterior | AG1: Passivos - exercício | AH1: Reforço de Capital - Exercício anterior | AI1: Reforço de Capital - Exercício | AJ1: Ações ou cotas - Exercício anterior | AK1: Ações ou cotas - Exercício | AL1: Capital Social Integralizado - Exercício anterior | AM1: Capital Social Integralizado - Exercício | AN1: Capital Social a Integralizar -Exercício anterior | AO1: Capital Social a Integralizar - Exercício | AP1: Rentabilidade
A2: AC | B2: Empresa de Processamento de Dados do Acre - ACREDATA | C2: ACREDATA | D2: 04.088.985/0001-00 | E2: ATIVA | F2: INFORMÁTICA E TECNOLOGIA DA INFORMAÇÃO | G2: EMPRESA PÚBLICA | H2: S.A. | I2: FECHADO | J2: NÃO | K2: NÃO | L2: DEPENDENTE | M2: 84 | N2: SIM | O2: SIM | P2: NÃO | R2: 13107416 | S2: 6325167.2 | T2: 13107416 | U2: 0 | V2: SIM | W2: 0 | X2: 0 | Y2: 0 | Z2: 11811972 | AA2: 1.037203e+08 | AB2: 0 | AC2: 0 | AD2: 11684206 | AE2: 13107416 | AF2: 0 | AG2: 0 | AH2: 0 | AI2: 0 | AJ2: 4396687.6 | AK2: 4396687.6 | AL2: 4396687.6 | AM2: 4396687.6 | AN2: 0 | AO2: 0 | AP2: =Z2*100/AA2 -> 11.388293
A3: AC | B3: Agencia de Negócios do Estado do Acre - ANAC | C3: ANAC | D3: 05.899.982/0001-19 | E3: ATIVA | F3: OUTROS | G3: SOCIEDADE DE ECONOMIA MISTA | H3: S.A. | I3: FECHADO | J3: NÃO | K3: NÃO | L3: DEPENDENTE | M3: 12 | N3: SIM | O3: SIM | P3: NÃO | R3: 8531737.6 | S3: 7155806.2 | T3: 10314428 | U3: 0 | V3: NÃO | W3: 407932.32 | X3: 0 | Y3: 99128.6 | Z3: -10051186 | AA3: 39712876 | AB3: 0 | AC3: 0 | AD3: 0 | AE3: 0 | AF3: 0 | AG3: 0 | AH3: 5563422.4 | AI3: 8531737.6 | AJ3: 0 | AK3: 0 | AL3: 1.5620548e+08 | AM3: 1.6473722e+08 | AN3: 3794518.8 | AO3: 9762781.2 | AP3: =Z3*100/AA3 -> -25.309639
A4: AC | B4: Administradora da Zona de Processamento de Exportação do Acre - AZPE/AC | C4: AZPE | D4: 12.467.990/0001-51 | E4: ATIVA | F4: DESENVOLVIMENTO REGIONAL | G4: SOCIEDADE DE ECONOMIA MISTA | H4: S.A. | I4: FECHADO | J4: NÃO | K4: NÃO | L4: DEPENDENTE | M4: 0 | N4: SIM | O4: SIM | P4: NÃO | R4: 0 | S4: 0 | T4: 0 | U4: 0 | V4: NÃO | W4: 0 | X4: 0 | Y4: 0 | Z4: 0 | AA4: 0 | AB4: 0 | AC4: 0 | AD4: 0 | AE4: 0 | AF4: 0 | AG4: 0 | AH4: 0 | AI4: 0 | AJ4: 0 | AK4: 0 | AL4: 0 | AM4: 0 | AN4: 0 | AO4: 0 | AP4: =Z4*100/AA4 -> #DIV/0!
A5: AC | B5: Banco do Estado do Acre - BANACRE | C5: BANACRE | D5: 04.064.077/0001-86 | E5: EM LIQUIDAÇÃO | F5: FINANCEIRO | G5: SOCIEDADE DE ECONOMIA MISTA | H5: S.A. | I5: FECHADO | J5: NÃO | K5: NÃO | L5: DEPENDENTE | M5: 12 | N5: SIM | O5: SIM | P5: NÃO | R5: 1776184.3 | S5: 1444341.2 | T5: 1643842.5 | U5: 2348.39 | V5: NÃO | W5: 109184.47 | X5: 0 | Y5: 0 | Z5: -2514600.7 | AA5: -1.9934195e+08 | AB5: 0 | AC5: 0 | AD5: 1780362.8 | AE5: 1774049 | AF5: 0 | AG5: 0 | AH5: 0 | AI5: 0 | AJ5: 0 | AK5: 0 | AL5: 24365821 | AM5: 24365821 | AN5: 0 | AO5: 0 | AP5: =Z5*100/AA5 -> 1.2614508
A6: AC | B6: Companhia de Armazéns e Entrepostos do Acre - CAGEACRE | C6: CAGEACRE | D6: 04.043.493/0001-06 | E6: ATIVA | F6: ABASTECIMENTO DE ALIMENTOS E OUTROS INSUMOS | G6: EMPRESA PÚBLICA | H6: OUTRAS | I6: FECHADO | J6: NÃO | K6: NÃO | L6: DEPENDENTE | M6: 155 | N6: NÃO | O6: SIM | P6: NÃO | R6: 14729465 | S6: 13419884 | T6: 14759182 | U6: 0 | V6: NÃO | W6: 215350.25 | X6: 0 | Y6: 548258.13 | Z6: 678045.71 | AA6: 7447035.2 | AB6: 0 | AC6: 0 | AD6: 19543507 | AE6: 14729465 | AF6: 305753.42 | AG6: 170846.03 | AH6: 0 | AI6: 0 | AJ6: 727.45 | AK6: 727.45 | AL6: 8219091 | AM6: 8219091 | AN6: 0 | AO6: 0 | AP6: =Z6*100/AA6 -> 9.1049081
A7: AC | B7: Companhia Agência de Desenvolvimento e Serviços Ambientais do Estado do Acre - CDSA | C7: CDSA | D7: 16.864.341/0001-45 | E7: ATIVA | F7: DESENVOLVIMENTO REGIONAL | G7: SOCIEDADE DE ECONOMIA MISTA | H7: S.A. | I7: FECHADO | J7: NÃO | K7: NÃO | L7: DEPENDENTE | M7: 13 | N7: SIM | O7: SIM | P7: NÃO | R7: 1521027 | S7: 1483227 | T7: 1483227 | U7: 0 | V7: NÃO | W7: 233705.73 | X7: 0 | Y7: 0 | Z7: -24631.91 | AA7: 3.0056081e+09 | AB7: 0 | AC7: 0 | AD7: 957768.34 | AE7: 1521027 | AF7: 973545.94 | AG7: 1483227 | AH7: 2447100 | AI7: 2400000 | AJ7: 3003209100 | AK7: 3005609100 | AL7: 3003209100 | AM7: 3005609100 | AN7: 3397100 | AO7: 997100 | AP7: =Z7*100/AA7 -> -0.00081953166
A8: AC | B8: Companhia Industrial de Laticínios do Acre - CILA | C8: CILA | D8: 04.061.693/0001-83 | E8: ATIVA | F8: ABASTECIMENTO DE ALIMENTOS E OUTROS INSUMOS | G8: EMPRESA PÚBLICA | H8: S.A. | I8: FECHADO | J8: NÃO | K8: SIM | L8: DEPENDENTE | M8: 29 | N8: SIM | O8: SIM | P8: NÃO | R8: 2820871.2 | S8: 2497093.8 | T8: 2820871.2 | U8: 1686.87 | V8: NÃO | W8: 2183003.7 | X8: 0 | Y8: 0 | Z8: 142443.37 | AA8: -88773663 | AB8: 0 | AC8: 0 | AD8: 2317412.3 | AE8: 2820871.2 | AF8: 2147999.3 | AG8: 1996951.8 | AH8: 0 | AI8: 0 | AJ8: 0 | AK8: 0 | AL8: 416.44 | AM8: 416.44 | AN8: 0 | AO8: 0 | AP8: =Z8*100/AA8 -> -0.16045679
A9: AC | B9: Companhia de Desenvolvimento Industrial do Acre - CODISACRE | C9: CODISACRE | D9: 04.039.277/0001-89 | E9: ATIVA | F9: DESENVOLVIMENTO REGIONAL | G9: EMPRESA PÚBLICA | H9: OUTRAS | I9: FECHADO | J9: NÃO | K9: SIM | L9: DEPENDENTE | M9: 37 | N9: SIM | O9: SIM | P9: NÃO | R9: 5026604.3 | S9: 3944525.1 | T9: 5010921 | U9: 244185.81 | V9: NÃO | W9: 198405.6 | X9: 0 | Y9: 0 | Z9: 693377.74 | AA9: 6665321.6 | AB9: 0 | AC9: 0 | AD9: 4779201.4 | AE9: 5010921 | AF9: 410259.38 | AG9: 397316.62 | AH9: 0 | AI9: 0 | AJ9: 0 | AK9: 0 | AL9: 3791691 | AM9: 3791691 | AN9: 0 | AO9: 0 | AP9: =Z9*100/AA9 -> 10.402765
A10: AC | B10: Companhia de Habitação do Acre - COHAB/ACRE | C10: COHAB | D10: 04.066.007/0001-67 | E10: ATIVA | F10: HABITAÇÃO E URBANIZAÇÃO | G10: SOCIEDADE DE ECONOMIA MISTA | H10: OUTRAS | I10: FECHADO | J10: NÃO | K10: NÃO | L10: DEPENDENTE | M10: 63 | N10: SIM | O10: SIM | P10: NÃO | R10: 7431327.1 | S10: 6325167.2 | T10: 9499084.6 | U10: 0 | V10: NÃO | W10: 270124.92 | X10: 0 | Y10: 0 | Z10: 3953141.1 | AA10: 79307669 | AB10: 0 | AC10: 0 | AD10: 6949505.2 | AE10: 8771679.9 | AF10: 8064674.4 | AG10: 7204783.3 | AH10: 0 | AI10: 0 | AJ10: 0.99 | AK10: 0.99 | AL10: 62840607 | AM10: 62840607 | AN10: 0 | AO10: 0 | AP10: =Z10*100/AA10 -> 4.9845635
A11: AC | B11: Companhia de Colonização do Acre - COLONACRE | C11: COLONACRE | D11: 04.039.673/0001-06 | E11: EM LIQUIDAÇÃO | F11: DESENVOLVIMENTO REGIONAL | G11: EMPRESA PÚBLICA | H11: OUTRAS | I11: FECHADO | J11: NÃO | K11: SIM | L11: DEPENDENTE | M11: 17 | N11: NÃO | O11: SIM | P11: NÃO | R11: 1705223.6 | S11: 1658046.4 | T11: 1658621.4 | U11: 0 | V11: NÃO | W11: 1040941.4 | X11: 0 | Y11: 0 | Z11: 46963.39 | AA11: 5690130.8 | AB11: 0 | AC11: 0 | AD11: 1397964.1 | AE11: 1705223.6 | AF11: 0 | AG11: 0 | AH11: 0 | AI11: 0 | AJ11: 3958917.2 | AK11: 3595917.2 | AL11: 3598917.2 | AM11: 3598917.2 | AN11: 0 | AO11: 0 | AP11: =Z11*100/AA11 -> 0.82534816
A12: AC | B12: Empresa de Assistência Técnica e Extensão Rural do Acre - EMATER | C12: EMATER | D12: 04.044.244/0001-27 | E12: ATIVA | F12: PESQUISA E ASSISTÊNCIA TÉCNICA AGROPECUÁRIA | G12: EMPRESA PÚBLICA | H12: OUTRAS | I12: FECHADO | J12: NÃO | K12: NÃO | L12: DEPENDENTE | M12: 152 | N12: SIM | O12: SIM | P12: NÃO | R12: 23737121 | S12: 18707804 | T12: 22994301 | U12: 0 | V12: NÃO | W12: 349852.72 | X12: 0 | Y12: 5040 | Z12: 167735.68 | AA12: -8249.79 | AB12: 0 | AC12: 0 | AD12: 21676919 | AE12: 23737121 | AF12: 0 | AG12: 0 | AH12: 2052870.8 | AI12: 2149510.2 | AJ12: 0 | AK12: 0 | AL12: 0 | AM12: 0 | AN12: 0 | AO12: 0 | AP12: =Z12*100/AA12 -> -2033.2115
A13: AC | B13: Companhia de Saneamento do Acre - SANACRE | C13: SANACRE | D13: 04.003.232/0001-54 | E13: ATIVA | F13: SANEAMENTO | G13: SOCIEDADE DE ECONOMIA MISTA | H13: OUTRAS | I13: FECHADO | J13: NÃO | K13: NÃO | L13: DEPENDENTE | M13: 189 | N13: SIM | O13: SIM | P13: NÃO | R13: 0 | S13: 22880993 | T13: 22972686 | U13: 0 | V13: NÃO | W13: 0 | X13: 0 | Y13: 0 | Z13: 91692.53 | AA13: 19805481 | AB13: 0 | AC13: 0 | AD13: 3364776.2 | AE13: 3547857.4 | AF13: 0 | AG13: 0 | AH13: 0 | AI13: 0 | AJ13: 0 | AK13: 0 | AL13: 0 | AM13: 0 | AN13: 0 | AO13: 0 | AP13: =Z13*100/AA13 -> 0.46296543
A14: AL | B14: Agência de Fomento de Alagoas - Desenvolve | C14: AFAL | D14: 10.769.660/0001-95 | E14: ATIVA | F14: FINANCEIRO | G14: SOCIEDADE DE ECONOMIA MISTA | H14: S.A. | I14: FECHADO | J14: NÃO | K14: SIM | L14: DEPENDENTE | M14: 57 | N14: SIM | O14: SIM | P14: NÃO | R14: -7615000 | S14: 651000 | T14: 8475000 | U14: 0 | V14: NÃO | W14: 119587 | X14: 0 | Y14: 0 | Z14: -7444000 | AA14: 45079000 | AC14: 0 | AD14: 0 | AE14: 0 | AF14: 0 | AG14: 0 | AH14: 0 | AI14: 0 | AJ14: 8041 | AK14: 8041 | AL14: 80414000 | AM14: 80414000 | AN14: 0 | AO14: 0 | AP14: =Z14*100/AA14 -> -16.513232
A15: AL | B15: Companhia Alagoana de Recursos Humanos e Patrimoniais | C15: CARHP | D15: 12.291.274/0001-66 | E15: EM LIQUIDAÇÃO | F15: HABITAÇÃO E URBANIZAÇÃO | G15: SOCIEDADE DE ECONOMIA MISTA | H15: S.A. | I15: FECHADO | J15: NÃO | K15: NÃO | L15: DEPENDENTE | M15: 1 | N15: NÃO | O15: SIM | P15: NÃO | R15: 918583.9 | S15: 16778.87 | T15: 376826.32 | U15: 323632.27 | V15: NÃO | W15: 218125.31 | X15: 0 | Y15: 0 | Z15: -22558098 | AA15: 19491992 | AC15: 0 | AD15: 5776972.9 | AE15: 2734522 | AF15: 1.0955497e+08 | AG15: 1.0961923e+08 | AH15: 0 | AI15: 0 | AJ15: 0 | AK15: 0 | AL15: 20251521 | AM15: 20251521 | AN15: 0 | AO15: 0 | AP15: =Z15*100/AA15 -> -115.73008
A16: AL | B16: Laboratório Industrial Farmacêutico | C16: LIFAL | D16: 12.343.158/0001-43 | E16: EM LIQUIDAÇÃO | F16: SAÚDE | G16: SOCIEDADE DE ECONOMIA MISTA | H16: S.A. | I16: FECHADO | J16: NÃO | K16: NÃO | L16: DEPENDENTE | M16: 0 | N16: NÃO | O16: SIM | P16: NÃO | R16: 416573.91 | S16: 4793.94 | T16: 4793.94 | U16: 0 | V16: NÃO | W16: 62321.22 | X16: 0 | Y16: 152320.29 | Z16: 86544.66 | AA16: -50970.82 | AC16: 0 | AD16: 354932.54 | AE16: 430375.27 | AF16: 837615.8 | AG16: 837615.8 | AH16: 0 | AI16: 0 | AJ16: 0 | AK16: 0 | AL16: 0 | AM16: 0 | AN16: 0 | AO16: 0 | AP16: =Z16*100/AA16 -> -169.79256
A17: AL | B17: Banco do Estado de Alagoas S.A | C17: PRODUBAN | D17: 12.275.749/0001-20 | E17: EM LIQUIDAÇÃO | F17: FINANCEIRO | G17: SOCIEDADE DE ECONOMIA MISTA | H17: S.A. | I17: FECHADO | J17: NÃO | K17: NÃO | L17: DEPENDENTE | M17: 3 | N17: NÃO | O17: SIM | P17: NÃO | R17: 538686.32 | S17: 554179.85 | T17: 20349597 | U17: 0 | V17: NÃO | W17: 325324.89 | X17: 0 | Y17: 0 | Z17: -20349597 | AA17: 1.2073279e+08 | AC17: 0 | AD17: 100000 | AE17: 100000 | AF17: 0 | AG17: 0 | AH17: 0 | AI17: 16000000 | AJ17: 6750 | AK17: 6750 | AL17: 4.998111e+08 | AM17: 4.998111e+08 | AN17: 0 | AO17: 0 | AP17: =Z17*100/AA17 -> -16.855071
A18: AL | B18: Serviços de Engenharia de Alagoas S.A | C18: SERVEAL | D18: 12.318.887/0001-40 | E18: EM LIQUIDAÇÃO | F18: OUTROS | G18: SOCIEDADE DE ECONOMIA MISTA | H18: S.A. | I18: FECHADO | J18: NÃO | K18: NÃO | L18: DEPENDENTE | M18: 5 | N18: NÃO | O18: SIM | P18: NÃO | R18: 539804.76 | S18: 41523.44 | T18: 42358.91 | U18: 0 | V18: NÃO | W18: 539804.72 | X18: 0 | Y18: 0 | Z18: 0 | AA18: -1653049.8 | AC18: 0 | AD18: 1018063.9 | AE18: 387314.54 | AF18: 3889423.1 | AG18: 3855251.4 | AH18: 0 | AI18: 0 | AJ18: 0 | AK18: 0 | AL18: -505486.95 | AM18: -505486.95 | AN18: 0 | AO18: 0 | AP18: =Z18*100/AA18 -> 0
A19: AL | B19: Alagoas Ativos S.A | C19: ALAtivos | D19: 29.218.037/0001-72 | E19: ATIVA | F19: GESTÃO DE ATIVOS | G19: EMPRESA PÚBLICA | H19: S.A. | I19: FECHADO | J19: NÃO | K19: NÃO | L19: NÃO DEPENDENTE | M19: 19 | N19: SIM | O19: SIM | P19: NÃO | R19: 5313174.6 | S19: 2192507.7 | T19: 7586434.2 | U19: 0 | V19: NÃO | W19: 405711.63 | X19: 0 | Y19: 0 | Z19: 646243.59 | AA19: 1354881.7 | AC19: 0 | AD19: 0 | AE19: 0 | AF19: 0 | AG19: 0 | AH19: 0 | AI19: 0 | AJ19: 0 | AK19: 0 | AL19: 10000000 | AM19: 0 | AN19: 0 | AO19: 0 | AP19: =Z19*100/AA19 -> 47.697419
A20: AL | B20: Gás de Alagoas S.A | C20: ALGÁS | D20: 69.983.484/0001-32 | E20: ATIVA | F20: GÁS E DERIVADOS | G20: SOCIEDADE DE ECONOMIA MISTA | H20: S.A. | I20: FECHADO | J20: NÃO | K20: NÃO | L20: NÃO DEPENDENTE | M20: 161 | N20: SIM | O20: SIM | P20: SIM | Q20: https://governanca,algas,com,br/carta-anual-de-politicas-publicas-e-governanca-corporativa | R20: 4.5279713e+08 | S20: 25539770 | T20: 4.5719368e+08 | U20: 34430658 | V20: NÃO | W20: 398267.27 | X20: 0 | Y20: 0 | Z20: 40882910 | AA20: 1.4065218e+08 | AC20: 10638724 | AD20: 0 | AE20: 0 | AF20: 0 | AG20: 0 | AH20: 0 | AI20: 0 | AJ20: 2873893 | AK20: 3212493.4 | AL20: 23729600 | AM20: 26525400 | AN20: 0 | AO20: 0 | AP20: =Z20*100/AA20 -> 29.066674
A21: AL | B21: Companhia de Saneamento de Alagoas | C21: CASAL | D21: 12.294.708/0001-81 | E21: ATIVA | F21: SANEAMENTO | G21: SOCIEDADE DE ECONOMIA MISTA | H21: S.A. | I21: FECHADO | J21: NÃO | K21: NÃO | L21: NÃO DEPENDENTE | M21: 856 | N21: SIM | O21: SIM | P21: SIM | Q21: https://www,casal,al,gov,br/arquivos/carta-anual-de-politicas-publicas-e-governanca-corporativa-2024/ | R21: 464911233 | S21: 109360615 | T21: 5.4383181e+08 | U21: 11453707 | V21: NÃO | W21: 475077.99 | X21: 0 | Y21: 23628.57 | Z21: 76660074 | AA21: 6571826958 | AC21: 0 | AD21: 0 | AE21: 0 | AF21: 0 | AG21: 0 | AH21: 44880272 | AI21: 51271902 | AJ21: 1.364436e+09 | AK21: 1.364436e+09 | AL21: 4.6968194e+08 | AM21: 5.2557004e+08 | AN21: 2.8769973e+08 | AO21: 2.3181163e+08 | AP21: =Z21*100/AA21 -> 1.1664956
A22: AL | B22: Companhia de Edição Impressão e Publicação de Alagoas | C22: CEPAL | D22: 04.308.836/0001-09 | E22: ATIVA | F22: COMUNICAÇÃO | G22: SOCIEDADE DE ECONOMIA MISTA | H22: S.A. | I22: FECHADO | J22: NÃO | K22: NÃO | L22: NÃO DEPENDENTE | M22: 119 | N22: SIM | O22: SIM | P22: NÃO | Q22: https://www,imprensaoficial,al,gov,br/storage/files/2025/04/Carta_Anual_de_Políticas_Públicas_CEPAL_Aprovada_Conselho_2024,pdf | R22: 17985778 | S22: 12885086 | T22: 20957137 | U22: 0 | V22: NÃO | W22: 298779.51 | X22: 0 | Y22: 0 | Z22: -5899240.4 | AA22: 217370.56 | AC22: 0 | AD22: 0 | AE22: 0 | AF22: 0 | AG22: 0 | AH22: 0 | AI22: 0 | AJ22: 10083000 | AK22: 10083000 | AL22: 10083000 | AM22: 10083000 | AN22: 0 | AO22: 0 | AP22: =Z22*100/AA22 -> -2713.9096
A23: AM | B23: Agência de Desenvolvimento Sustentável do Amazonas | C23: ADS | D23: 05.867.581/0001-87 | E23: ATIVA | F23: DESENVOLVIMENTO REGIONAL | G23: EMPRESA PÚBLICA | H23: S.A. | I23: FECHADO | J23: NÃO | K23: NÃO | L23: DEPENDENTE | M23: 83 | N23: SIM | O23: SIM | P23: NÃO | Q23: Não possui | R23: 1890024 | S23: 4164370.4 | T23: 1.3566569e+08 | U23: 0 | V23: NÃO | W23: 180416.58 | X23: 0 | Y23: 133966.4 | Z23: -4743532 | AA23: 795178.7 | AB23: 0 | AC23: 0 | AD23: 1.0214802e+08 | AE23: 1.2582989e+08 | AF23: 0 | AG23: 0 | AH23: 0 | AI23: 0 | AJ23: 0 | AK23: 0 | AL23: 10000000 | AM23: 10000000 | AN23: 0 | AO23: 0 | AP23: =Z23*100/AA23 -> -596.5366
A24: AM | B24: Empresa Estadual de Turismo | C24: AMAZONASTUR | D24: 05.662.046/0001-90 | E24: ATIVA | F24: TURISMO | G24: EMPRESA PÚBLICA | H24: OUTRAS | I24: FECHADO | J24: NÃO | K24: NÃO | L24: DEPENDENTE | M24: 144 | N24: SIM | O24: SIM | P24: SIM | Q24: https://www,amazonastur,am,gov,br/wpcontent/ uploads/2024/10/amazonastur-cartaservicos- 2024,pdf | R24: 631607.64 | S24: 13648435 | T24: 1.0485808e+08 | U24: 38772283 | V24: NÃO | W24: 407740 | X24: 0 | Y24: 0 | Z24: -803617.85 | AA24: 4189166.1 | AB24: 0 | AC24: 0 | AD24: 71978546 | AE24: 1.0425863e+08 | AF24: 2807045.4 | AG24: 6734566.2 | AH24: 0 | AI24: 0 | AJ24: 1 | AK24: 1 | AL24: 27123375 | AM24: 27123375 | AN24: 0 | AO24: 0 | AP24: =Z24*100/AA24 -> -19.183242
A25: AM | B25: Cia. de Desenvolvimento do Estado do Amazonas | C25: CIAMA | D25: 00.624.961/0001-77 | E25: ATIVA | F25: DESENVOLVIMENTO REGIONAL | G25: SOCIEDADE DE ECONOMIA MISTA | H25: S.A. | I25: FECHADO | J25: NÃO | K25: NÃO | L25: DEPENDENTE | M25: 191 | N25: SIM | O25: SIM | P25: NÃO | Q25: www,ciama,am,gov,br | R25: 0 | S25: 30883607 | T25: 35833134 | U25: 0 | V25: NÃO | W25: 758106.55 | X25: 0 | Y25: 6500 | Z25: -18991279 | AA25: 53266635 | AB25: 0 | AC25: 0 | AD25: 30817836 | AE25: 17074546 | AF25: 0 | AG25: 0 | AH25: 0 | AI25: 16526312 | AJ25: 62880631 | AK25: 66058773 | AL25: 3.2697928e+08 | AM25: 3.4350559e+08 | AN25: 49020720 | AO25: 32494407 | AP25: =Z25*100/AA25 -> -35.653235
A26: AM | B26: Cia. de Saneamento do Amazonas | C26: COSAMA | D26: 04.406.195/0001-25 | E26: ATIVA | F26: SANEAMENTO | G26: SOCIEDADE DE ECONOMIA MISTA | H26: S.A. | I26: FECHADO | J26: NÃO | K26: NÃO | L26: DEPENDENTE | M26: 522 | N26: SIM | O26: SIM | P26: NÃO | Q26: Não foi publicada carta anual, | R26: 73990521 | S26: 45340671 | T26: 83896774 | U26: 4303097.2 | V26: NÃO | W26: 469688.87 | X26: 0 | Y26: 4525.34 | Z26: -8231341.9 | AA26: -22972209 | AB26: 0 | AC26: 0 | AD26: 47283701 | AE26: 49576266 | AF26: 0 | AG26: 0 | AH26: 4042877 | AI26: 1290000 | AJ26: 22094870827 | AK26: 22094870827 | AL26: 5.3386274e+08 | AM26: 5.3386274e+08 | AN26: 0 | AO26: 0 | AP26: =Z26*100/AA26 -> 35.831739
A27: AM | B27: Agência de Fomento do Estado do Amazonas | C27: AFEAM | D27: 03.183.937/0001-38 | E27: ATIVA | F27: FINANCEIRO | G27: EMPRESA PÚBLICA | H27: S.A. | I27: FECHADO | J27: NÃO | K27: NÃO | L27: NÃO DEPENDENTE | M27: 253 | N27: SIM | O27: SIM | P27: SIM | Q27: https://www,afeam,am,gov,br/wpcontent/ uploads/2025/04/CARTAANUAL¿ 2024,pdf | R27: 26835089 | S27: 50347133 | T27: 3.723726e+08 | U27: 3.2202546e+08 | V27: NÃO | W27: 567085.72 | X27: 0 | Y27: 34305.43 | Z27: 14463130 | AA27: 1.2578599e+08 | AB27: 0 | AC27: 0 | AD27: 0 | AE27: 0 | AF27: 0 | AG27: 0 | AH27: 0 | AI27: 0 | AJ27: 103963256 | AK27: 106465046 | AL27: 103963256 | AM27: 106465046 | AN27: 0 | AO27: 0 | AP27: =Z27*100/AA27 -> 11.498204
A28: AM | B28: Cia. Amazonense de Desenvolvimento e Mobilização de Ativos | C28: CADA | D28: 40.182.478/0001-02 | E28: ATIVA | F28: GESTÃO DE ATIVOS | G28: EMPRESA PÚBLICA | H28: S.A. | I28: FECHADO | J28: NÃO | K28: NÃO | L28: NÃO DEPENDENTE | M28: 26 | N28: SIM | O28: SIM | P28: SIM | Q28: https://www,cada,am,gov,br/wpcontent/uploads/2025/02/Carta-Anual-2025-Data-Base-2024,pdf | R28: 765121 | S28: 4383063 | T28: 4974652 | U28: 0 | V28: NÃO | W28: 439200 | X28: 0 | Y28: 6500 | Z28: 6811743 | AA28: 153408 | AB28: 0 | AC28: 0 | AD28: 0 | AE28: 0 | AF28: 0 | AG28: 0 | AH28: 6000000 | AI28: 4000000 | AJ28: 15000000 | AK28: 19000000 | AL28: 15000000 | AM28: 19000000 | AN28: 0 | AO28: 0 | AP28: =Z28*100/AA28 -> 4440.2789
A29: AM | B29: Cia. de Gás do Amazonas | C29: CIGAS | D29: 00.624.964/0001-00 | E29: ATIVA | F29: GÁS E DERIVADOS | G29: SOCIEDADE DE ECONOMIA MISTA | H29: S.A. | I29: FECHADO | J29: NÃO | K29: NÃO | L29: NÃO DEPENDENTE | M29: 230 | N29: SIM | O29: SIM | P29: NÃO | Q29: https://www,cigas-am,com,br/relatorio-de-sustentabilidade | R29: 3.5530374e+09 | S29: 2056766.3 | T29: 3.3761082e+09 | U29: 22339240 | V29: SIM | W29: 765000 | X29: 45000 | Y29: 14048 | Z29: 1.9728408e+08 | AA29: 5.0508971e+08 | AB29: 0 | AC29: 11365846 | AD29: 0 | AE29: 0 | AF29: 0 | AG29: 0 | AH29: 0 | AI29: 0 | AJ29: 12059543 | AK29: 12059543 | AL29: 45042129 | AM29: 58100045 | AN29: 0 | AO29: 0 | AP29: =Z29*100/AA29 -> 39.059216
A30: AM | B30: Processamento de Dados do Amazonas | C30: PRODAM | D30: 04.407.920/0001-80 | E30: ATIVA | F30: INFORMÁTICA E TECNOLOGIA DA INFORMAÇÃO | G30: SOCIEDADE DE ECONOMIA MISTA | H30: S.A. | I30: FECHADO | J30: NÃO | K30: NÃO | L30: NÃO DEPENDENTE | M30: 446 | N30: SIM | O30: SIM | P30: SIM | Q30: https://prodam,am,gov,br/acesso-a-informacao/carta-de-governanca-2024/ | R30: 136009915 | S30: 69725561 | T30: 78824023 | U30: 9098462 | V30: NÃO | W30: 730797.6 | X30: 0 | Y30: 23926.98 | Z30: 9749845 | AA30: 25157069 | AB30: 0 | AC30: 0 | AD30: 0 | AE30: 0 | AF30: 0 | AG30: 0 | AH30: 0 | AI30: 0 | AJ30: 99.89 | AK30: 99.89 | AL30: 45193991 | AM30: 45193991 | AN30: 0 | AO30: 0 | AP30: =Z30*100/AA30 -> 38.755886
A31: AP | B31: COMPANHIA DE ÁGUA E ESGOTO DO AMAPÁ | C31: CAESA | D31: 05.976.311/0001-04 | E31: ATIVA | F31: SANEAMENTO | G31: SOCIEDADE DE ECONOMIA MISTA | H31: S.A. | I31: FECHADO | J31: NÃO | K31: NÃO | L31: DEPENDENTE | M31: 298 | N31: SIM | O31: SIM | P31: NÃO | Q31: caesa,portal,ap,gov,br | R31: 2764377.3 | S31: 45689258 | T31: 1.2608268e+08 | U31: 519101.98 | V31: NÃO | W31: 284698.07 | X31: 0 | Y31: 200076.6 | Z31: -1.233183e+08 | AA31: 1.2129848e+08 | AB31: 0 | AC31: 0 | AD31: 51326173 | AE31: 51535695 | AF31: 1.5857231e+08 | AG31: 1.1186538e+08 | AH31: 51326173 | AI31: 51535695 | AJ31: 5245225458 | AK31: 5245225458 | AL31: 5.0695917e+08 | AM31: 5.5982014e+08 | AN31: 52860967 | AO31: 52607136 | AP31: =Z31*100/AA31 -> -101.66516
A32: AP | B32: AGÊNCIA DE FOMENTO POPULAR | C32: AFAP | D32: 02.929.977/0001-13 | E32: ATIVA | F32: FINANCEIRO | G32: EMPRESA PÚBLICA | H32: S.A. | I32: FECHADO | J32: NÃO | K32: NÃO | L32: NÃO DEPENDENTE | M32: 99 | N32: SIM | O32: SIM | P32: NÃO | R32: 11665247 | S32: 4546633.4 | T32: 13015641 | U32: 0 | V32: NÃO | W32: 204363.69 | X32: 0 | Y32: 63428.18 | Z32: -1045966.9 | AA32: 16811614 | AB32: 0 | AC32: 0 | AD32: 0 | AE32: 0 | AF32: 0 | AG32: 0 | AH32: 0 | AI32: 0 | AJ32: 39255740 | AK32: 39255740 | AL32: 34455740 | AM32: 39255740 | AN32: 34455740 | AO32: 39255740 | AP32: =Z32*100/AA32 -> -6.2216926
A33: AP | B33: COMPANHIA DE GÁS DO AMAPÁ | C33: GASAP | D33: 05.943.400/0001-54 | E33: ATIVA | F33: GÁS E DERIVADOS | G33: SOCIEDADE DE ECONOMIA MISTA | H33: S.A. | I33: FECHADO | J33: NÃO | K33: NÃO | L33: NÃO DEPENDENTE | M33: 2 | N33: SIM | O33: SIM | P33: NÃO | Q33: https://gasap,com,br/acesso-a-informacao/governanca/carta-anual-de-governanca | R33: 0 | S33: 169282.13 | T33: 312664.81 | U33: 0 | V33: NÃO | W33: 58275 | X33: 0 | Y33: 0 | Z33: 332463.03 | AA33: 135120.81 | AB33: 0 | AC33: 0 | AD33: 0 | AE33: 0 | AF33: 0 | AG33: 0 | AH33: 0 | AI33: 0 | AJ33: 790500 | AK33: 790500 | AL33: 2999000 | AM33: 31000 | AN33: 101000 | AO33: 0 | AP33: =Z33*100/AA33 -> 246.04872
A34: BA | B34: BAHIA PESCA S.A. | C34: BAHIAPESCA | D34: 13.187.745/0001-53 | E34: ATIVA | F34: ABASTECIMENTO DE ALIMENTOS E OUTROS INSUMOS | G34: SOCIEDADE DE ECONOMIA MISTA | H34: S.A. | I34: FECHADO | J34: NÃO | K34: NÃO | L34: DEPENDENTE | M34: 110 | N34: SIM | O34: SIM | P34: NÃO | Q34: https://www,ba,gov,br/bahiapesca/sites/site-bahiapesca/files/2024-12/Carta%20Anual%20exerc%C3%ADcio%202023,pdf | R34: 83617 | S34: 13857900 | T34: 28561678 | U34: 865276 | V34: NÃO | W34: 379709.85 | X34: 0 | Y34: 0 | Z34: 3377901 | AA34: -3362003 | AB34: 0 | AC34: 0 | AD34: 5400883 | AE34: 6890791.4 | AF34: 2558600 | AG34: 2762929 | AH34: 0 | AI34: 0 | AJ34: 16079007 | AK34: 16079007 | AL34: 4824688.6 | AM34: 4824688.6 | AN34: 0 | AO34: 0 | AP34: =Z34*100/AA34 -> -100.47287
A35: BA | B35: COMPANHA DE DESENVOLVIMENTO E AÇÃO REGIONAL | C35: CAR | D35: 13.221.247/0001-80 | E35: ATIVA | F35: DESENVOLVIMENTO REGIONAL | G35: EMPRESA PÚBLICA | H35: S.A. | I35: FECHADO | J35: NÃO | K35: NÃO | L35: DEPENDENTE | M35: 375 | N35: SIM | O35: SIM | P35: NÃO | Q35: https://www,car,ba,gov,br/sites/default/files/2025-01/Carta%20Anual%202025,pdf | R35: 63124352 | S35: 43114341 | T35: 60917575 | U35: 0 | V35: NÃO | W35: 463700.92 | X35: 0 | Y35: 4892.8 | Z35: 2270183.7 | AA35: -37037212 | AB35: 0 | AC35: 0 | AD35: 51115067 | AE35: 62005726 | AF35: 0 | AG35: 0 | AH35: 0 | AI35: 0 | AJ35: 13542532 | AK35: 13542532 | AL35: 13542532 | AM35: 13542532 | AN35: 12549846 | AO35: 12513332 | AP35: =Z35*100/AA35 -> -6.1294669
A36: BA | B36: COMPANHIA BAIANA DE PESQUISA MINERAL | C36: CBPM | D36: 13.554.910/0001-68 | E36: ATIVA | F36: MINERAÇÃO | G36: SOCIEDADE DE ECONOMIA MISTA | H36: S.A. | I36: FECHADO | J36: NÃO | K36: NÃO | L36: DEPENDENTE | M36: 141 | N36: SIM | O36: SIM | P36: NÃO | Q36: http://www,cbpm,ba,gov,br/transparencia/carta-anual-de-politicas-publicas-e-governanca-corporativa/ | R36: 57231013 | S36: 53051335 | T36: 95695329 | U36: 787226 | V36: NÃO | W36: 463398.48 | X36: 0 | Y36: 16133.11 | Z36: -10532826 | AA36: -83137845 | AB36: 0 | AC36: 0 | AD36: 6087023.9 | AE36: 8346554.7 | AF36: 0 | AG36: 0 | AH36: 0 | AI36: 0 | AJ36: 99991387 | AK36: 99991387 | AL36: 100000000 | AM36: 100000000 | AN36: 0 | AO36: 0 | AP36: =Z36*100/AA36 -> 12.669111
A37: BA | B37: COMPANHIA DE ENGENHARIA HÍDRICA E DE SANEAMENTO DA BAHIA | C37: CERB | D37: 13.529.136/0001-35 | E37: ATIVA | F37: SANEAMENTO | G37: SOCIEDADE DE ECONOMIA MISTA | H37: S.A. | I37: FECHADO | J37: NÃO | K37: NÃO | L37: DEPENDENTE | M37: 1055 | N37: SIM | O37: SIM | P37: SIM | Q37: http://www,cerb,ba,gov,br/sites/www,cerb,ba,gov,br/files/a_cerb/nosso_papel/page/files/CARTA_ANUAL_2024_VF,pdf | R37: 12267646 | S37: 40632220 | T37: 1.5975587e+08 | U37: 86292045 | V37: SIM | W37: 445266.58 | X37: 17139.34 | Y37: 0 | Z37: 14284705 | AA37: 7166576.2 | AB37: 0 | AC37: 0 | AD37: 1.2280125e+08 | AE37: 1.4710052e+08 | AF37: 0 | AG37: 59733784 | AH37: 0 | AI37: 0 | AJ37: 99.65 | AK37: 99.65 | AL37: 131206906 | AM37: 131206906 | AN37: 0 | AO37: 0 | AP37: =Z37*100/AA37 -> 199.32399
A38: BA | B38: COMPANHIA DE DESENVOLVIMENTO URBANO DO ESTADO DA BAHIA | C38: CONDER | D38: 13.595.251/0001-08 | E38: ATIVA | F38: HABITAÇÃO E URBANIZAÇÃO | G38: EMPRESA PÚBLICA | H38: OUTRAS | I38: FECHADO | J38: NÃO | K38: NÃO | L38: DEPENDENTE | M38: 347 | N38: SIM | O38: SIM | P38: NÃO | Q38: https://www,conder,ba,gov,br/sites/default/files/2024-04/CARTA GOVERNANÇA 2024_0,pdf | R38: 3.7690629e+08 | S38: 42386836 | T38: 3.9613606e+08 | U38: 0 | V38: NÃO | W38: 451672.48 | X38: 0 | Y38: 11888.24 | Z38: -14979511 | AA38: 1.7510069e+08 | AB38: 0 | AC38: 0 | AD38: 1.3169547e+09 | AE38: 1.1263136e+09 | AF38: 0 | AG38: 0 | AH38: 0 | AI38: 0 | AJ38: 16803754 | AK38: 16803754 | AL38: 16803753 | AM38: 16803754 | AN38: 0 | AO38: 0 | AP38: =Z38*100/AA38 -> -8.554798
A39: BA | B39: COMPANHIA DE TRANSPORTE DO ESTADO DA BAHIA | C39: CTB | D39: 03.231.999/0001-78 | E39: ATIVA | F39: TRANSPORTE | G39: EMPRESA PÚBLICA | H39: S.A. | I39: FECHADO | J39: NÃO | K39: NÃO | L39: DEPENDENTE | M39: 82 | N39: SIM | O39: SIM | P39: NÃO | R39: 5213305 | S39: 23508721 | T39: 2.6093772e+08 | U39: 237429000 | V39: NÃO | W39: 433360.48 | X39: 0 | Y39: 0 | Z39: -11730795 | AA39: 40896905 | AB39: 0 | AC39: 0 | AD39: 59945660 | AE39: 2.7735765e+08 | AF39: 0 | AG39: 0 | AH39: 0 | AI39: 0 | AJ39: 159700077 | AK39: 159700077 | AL39: 1.3965449e+08 | AM39: 1.3965449e+08 | AN39: 22737270 | AO39: 22737270 | AP39: =Z39*100/AA39 -> -28.68382
A40: BA | B40: COMPANHIA DE GÁS DA BAHIA | C40: BAHIAGÁS | D40: 34.432.153/0001-20 | E40: ATIVA | F40: GÁS E DERIVADOS | G40: SOCIEDADE DE ECONOMIA MISTA | H40: S.A. | I40: FECHADO | J40: NÃO | K40: NÃO | L40: NÃO DEPENDENTE | M40: 611 | N40: SIM | O40: SIM | P40: SIM | Q40: https://www,bahiagas,com,br/sobre-a-bahiagas/cartas-anuais | R40: 3.1283853e+09 | S40: 1.0301229e+08 | T40: 5.5297003e+08 | U40: 2.3625441e+08 | V40: SIM | W40: 560751.36 | X40: 103582.81 | Y40: 0 | Z40: 1.9768137e+08 | AA40: 1.1378639e+09 | AB40: 0 | AC40: 66931377 | AD40: 0 | AE40: 0 | AF40: 0 | AG40: 0 | AH40: 0 | AI40: 0 | AJ40: 13490874 | AK40: 15162188 | AL40: 3.1672674e+08 | AM40: 3.5596433e+08 | AN40: 0 | AO40: 0 | AP40: =Z40*100/AA40 -> 17.373023
...

Sheet ex2024 (fórmulas)
A1: Liana | B1: UF | C1: Estatal | D1: Sigla | E1: CNPJ | F1: Situação | G1: Setor | H1: Espécie | I1: Organização jurídica | J1: Tipo de Capital | K1: Listada em Bolsa | L1: É Subsidiária | M1: Dependência | N1: Número de Empregados (incluindo temporários e terceirizados) | O1: Checagem de empragados | P1: Possui Conselho de Administração | Q1: Possui Conselho Fiscal | R1: Possui Comitê de Autidoria | S1: Link Carta Anual | T1: Receita Líquida Operacional | U1: Despesa com Pessoal, incluindo temporários e terceirizados (por competência) | V1: Checagem de Despesa com pessoal | W1: Despesa Total (por competência) | X1: Investimento (por competência) | Y1: Foi Distribuído PLR ou RVA no exercício | Z1: Remuneração bruta total paga no ano (empregado que recebeu a maior remuneração) | AA1: PLR ou RVA pagos no ano (empregado que recebeu a maior remuneração) | AB1: Indenizações pagas no ano (empregado que recebeu a maior remuneração) | AC1: Lucro / Prejuízo Líquido do Exercício | AD1: Distribuiu PLR tendo prejuízo | AE1: Patrimônio Líquido | AF1: Valor de Mercado | AG1: Dividendos e Juros sobre Capital Próprio pagos ao Tesouro Estadual / Municipal (pago) | AH1: Subvenções - Exercício anterior | AI1: Subvenções - Exercício | AJ1: INDÍCIO DE DEPENDÊNCIA - SUBVENÇÃO | AK1: Passivos - Exercício anterior | AL1: Passivos - exercício | AM1: Reforço de Capital - Exercício anterior | AN1: Reforço de Capital - Exercício | AO1: Ações ou cotas - Exercício anterior | AP1: Ações ou cotas - Exercício | AQ1: Variação das Ações | AR1: Capital Social Integralizado - Exercício anterior | AS1: Capital Social Integralizado - Exercício | AT1: Capital Social a Integralizar -Exercício anterior | AU1: Capital Social a Integralizar - Exercício | AV1: Variação do Capital Social | AW1: Aumento do Capital ou Participação Acionária | AX1: Não dependente com aporte de capital | AY1: INDÍCIO DE DEPENDÊNCIA - APORTE DE CAPITAL | AZ1: Rentabilidade
B2: AC | C2: Empresa de Processamento de Dados do Acre - ACREDATA | D2: ACREDATA | E2: 04.088.985/0001-00 | F2: ATIVA | G2: INFORMÁTICA E TECNOLOGIA DA INFORMAÇÃO | H2: EMPRESA PÚBLICA | I2: S.A. | J2: FECHADO | K2: NÃO | L2: NÃO | M2: DEPENDENTE | N2: 84 | O2: =IF(AND(F2="ATIVA",VALUE(N2)=0),"VERIFICAR","OK") -> OK | P2: SIM | Q2: SIM | R2: NÃO | T2: 13107416 | U2: 6325167.2 | V2: =IF(AND(VALUE(N2)=0,VALUE(U2)>0),"VERIFICAR","OK") -> OK | W2: 13107416 | X2: 0 | Y2: SIM | Z2: 0 | AA2: 0 | AB2: 0 | AC2: 11811972 | AD2: =IF(AND(Y2="SIM",VALUE(AC2)<0),"VERIFICAR","OK") -> OK | AE2: 1.037203e+08 | AF2: 0 | AG2: 0 | AH2: 11684206 | AI2: 13107416 | AJ2: =IF(AND(M2="NÃO DEPENDENTE",VALUE(AI2)>0),"INDÍCIO DE DEPENDÊNCIA POR SUBVENÇÃO","OK") -> OK | AK2: 0 | AL2: 0 | AM2: 0 | AN2: 0 | AO2: 4396687.6 | AP2: 4396687.6 | AQ2: =AP2-AO2 -> 0 | AR2: 4396687.6 | AS2: 4396687.6 | AT2: 0 | AU2: 0 | AV2: =(AS2-AR2)+(AU2) -> 0 | AW2: =IF(OR(VALUE(AQ2)>0,VALUE(AV2)>0),"SIM","NÃO") -> NÃO | AX2: =IF(AND(M2="NÃO DEPENDENTE",VALUE(AN2)>0),"VER CAPITAL","OK") -> OK | AY2: =IF(AND(AX2="VER CAPITAL",AW2="NÃO"),"INDÍCIO DE DEPENDÊNCIA POR CAPITAL","OK") -> OK | AZ2: =AC2*100/AE2 -> 11.388293
B3: AC | C3: Agencia de Negócios do Estado do Acre - ANAC | D3: ANAC | E3: 05.899.982/0001-19 | F3: ATIVA | G3: OUTROS | H3: SOCIEDADE DE ECONOMIA MISTA | I3: S.A. | J3: FECHADO | K3: NÃO | L3: NÃO | M3: DEPENDENTE | N3: 12 | O3: =IF(AND(F3="ATIVA",VALUE(N3)=0),"VERIFICAR","OK") -> OK | P3: SIM | Q3: SIM | R3: NÃO | T3: 8531737.6 | U3: 7155806.2 | V3: =IF(AND(VALUE(N3)=0,VALUE(U3)>0),"VERIFICAR","OK") -> OK | W3: 10314428 | X3: 0 | Y3: NÃO | Z3: 407932.32 | AA3: 0 | AB3: 99128.6 | AC3: -10051186 | AD3: =IF(AND(Y3="SIM",VALUE(AC3)<0),"VERIFICAR","OK") -> OK | AE3: 39712876 | AF3: 0 | AG3: 0 | AH3: 0 | AI3: 0 | AJ3: =IF(AND(M3="NÃO DEPENDENTE",VALUE(AI3)>0),"INDÍCIO DE DEPENDÊNCIA POR SUBVENÇÃO","OK") -> OK | AK3: 0 | AL3: 0 | AM3: 5563422.4 | AN3: 8531737.6 | AO3: 0 | AP3: 0 | AQ3: =AP3-AO3 -> 0 | AR3: 1.5620548e+08 | AS3: 1.6473722e+08 | AT3: 3794518.8 | AU3: 9762781.2 | AV3: =(AS3-AR3)+(AU3) -> 18294519 | AW3: =IF(OR(VALUE(AQ3)>0,VALUE(AV3)>0),"SIM","NÃO") -> SIM | AX3: =IF(AND(M3="NÃO DEPENDENTE",VALUE(AN3)>0),"VER CAPITAL","OK") -> OK | AY3: =IF(AND(AX3="VER CAPITAL",AW3="NÃO"),"INDÍCIO DE DEPENDÊNCIA POR CAPITAL","OK") -> OK | AZ3: =AC3*100/AE3 -> -25.309639
B4: AC | C4: Administradora da Zona de Processamento de Exportação do Acre - AZPE/AC | D4: AZPE | E4: 12.467.990/0001-51 | F4: ATIVA | G4: DESENVOLVIMENTO REGIONAL | H4: SOCIEDADE DE ECONOMIA MISTA | I4: S.A. | J4: FECHADO | K4: NÃO | L4: NÃO | M4: DEPENDENTE | N4: 0 | O4: =IF(AND(F4="ATIVA",VALUE(N4)=0),"VERIFICAR","OK") -> VERIFICAR | P4: SIM | Q4: SIM | R4: NÃO | T4: 0 | U4: 0 | V4: =IF(AND(VALUE(N4)=0,VALUE(U4)>0),"VERIFICAR","OK") -> OK | W4: 0 | X4: 0 | Y4: NÃO | Z4: 0 | AA4: 0 | AB4: 0 | AC4: 0 | AD4: =IF(AND(Y4="SIM",VALUE(AC4)<0),"VERIFICAR","OK") -> OK | AE4: 0 | AF4: 0 | AG4: 0 | AH4: 0 | AI4: 0 | AJ4: =IF(AND(M4="NÃO DEPENDENTE",VALUE(AI4)>0),"INDÍCIO DE DEPENDÊNCIA POR SUBVENÇÃO","OK") -> OK | AK4: 0 | AL4: 0 | AM4: 0 | AN4: 0 | AO4: 0 | AP4: 0 | AQ4: =AP4-AO4 -> 0 | AR4: 0 | AS4: 0 | AT4: 0 | AU4: 0 | AV4: =(AS4-AR4)+(AU4) -> 0 | AW4: =IF(OR(VALUE(AQ4)>0,VALUE(AV4)>0),"SIM","NÃO") -> NÃO | AX4: =IF(AND(M4="NÃO DEPENDENTE",VALUE(AN4)>0),"VER CAPITAL","OK") -> OK | AY4: =IF(AND(AX4="VER CAPITAL",AW4="NÃO"),"INDÍCIO DE DEPENDÊNCIA POR CAPITAL","OK") -> OK | AZ4: =AC4*100/AE4 -> #DIV/0!
B5: AC | C5: Banco do Estado do Acre - BANACRE | D5: BANACRE | E5: 04.064.077/0001-86 | F5: EM LIQUIDAÇÃO | G5: FINANCEIRO | H5: SOCIEDADE DE ECONOMIA MISTA | I5: S.A. | J5: FECHADO | K5: NÃO | L5: NÃO | M5: DEPENDENTE | N5: 12 | O5: =IF(AND(F5="ATIVA",VALUE(N5)=0),"VERIFICAR","OK") -> OK | P5: SIM | Q5: SIM | R5: NÃO | T5: 1776184.3 | U5: 1444341.2 | V5: =IF(AND(VALUE(N5)=0,VALUE(U5)>0),"VERIFICAR","OK") -> OK | W5: 1643842.5 | X5: 2348.39 | Y5: NÃO | Z5: 109184.47 | AA5: 0 | AB5: 0 | AC5: -2514600.7 | AD5: =IF(AND(Y5="SIM",VALUE(AC5)<0),"VERIFICAR","OK") -> OK | AE5: -1.9934195e+08 | AF5: 0 | AG5: 0 | AH5: 1780362.8 | AI5: 1774049 | AJ5: =IF(AND(M5="NÃO DEPENDENTE",VALUE(AI5)>0),"INDÍCIO DE DEPENDÊNCIA POR SUBVENÇÃO","OK") -> OK | AK5: 0 | AL5: 0 | AM5: 0 | AN5: 0 | AO5: 0 | AP5: 0 | AQ5: =AP5-AO5 -> 0 | AR5: 24365821 | AS5: 24365821 | AT5: 0 | AU5: 0 | AV5: =(AS5-AR5)+(AU5) -> 0 | AW5: =IF(OR(VALUE(AQ5)>0,VALUE(AV5)>0),"SIM","NÃO") -> NÃO | AX5: =IF(AND(M5="NÃO DEPENDENTE",VALUE(AN5)>0),"VER CAPITAL","OK") -> OK | AY5: =IF(AND(AX5="VER CAPITAL",AW5="NÃO"),"INDÍCIO DE DEPENDÊNCIA POR CAPITAL","OK") -> OK | AZ5: =AC5*100/AE5 -> 1.2614508
B6: AC | C6: Companhia de Armazéns e Entrepostos do Acre - CAGEACRE | D6: CAGEACRE | E6: 04.043.493/0001-06 | F6: ATIVA | G6: ABASTECIMENTO DE ALIMENTOS E OUTROS INSUMOS | H6: EMPRESA PÚBLICA | I6: OUTRAS | J6: FECHADO | K6: NÃO | L6: NÃO | M6: DEPENDENTE | N6: 155 | O6: =IF(AND(F6="ATIVA",VALUE(N6)=0),"VERIFICAR","OK") -> OK | P6: NÃO | Q6: SIM | R6: NÃO | T6: 14729465 | U6: 13419884 | V6: =IF(AND(VALUE(N6)=0,VALUE(U6)>0),"VERIFICAR","OK") -> OK | W6: 14759182 | X6: 0 | Y6: NÃO | Z6: 215350.25 | AA6: 0 | AB6: 548258.13 | AC6: 678045.71 | AD6: =IF(AND(Y6="SIM",VALUE(AC6)<0),"VERIFICAR","OK") -> OK | AE6: 7447035.2 | AF6: 0 | AG6: 0 | AH6: 19543507 | AI6: 14729465 | AJ6: =IF(AND(M6="NÃO DEPENDENTE",VALUE(AI6)>0),"INDÍCIO DE DEPENDÊNCIA POR SUBVENÇÃO","OK") -> OK | AK6: 305753.42 | AL6: 170846.03 | AM6: 0 | AN6: 0 | AO6: 727.45 | AP6: 727.45 | AQ6: =AP6-AO6 -> 0 | AR6: 8219091 | AS6: 8219091 | AT6: 0 | AU6: 0 | AV6: =(AS6-AR6)+(AU6) -> 0 | AW6: =IF(OR(VALUE(AQ6)>0,VALUE(AV6)>0),"SIM","NÃO") -> NÃO | AX6: =IF(AND(M6="NÃO DEPENDENTE",VALUE(AN6)>0),"VER CAPITAL","OK") -> OK | AY6: =IF(AND(AX6="VER CAPITAL",AW6="NÃO"),"INDÍCIO DE DEPENDÊNCIA POR CAPITAL","OK") -> OK | AZ6: =AC6*100/AE6 -> 9.1049081
B7: AC | C7: Companhia Agência de Desenvolvimento e Serviços Ambientais do Estado do Acre - CDSA | D7: CDSA | E7: 16.864.341/0001-45 | F7: ATIVA | G7: DESENVOLVIMENTO REGIONAL | H7: SOCIEDADE DE ECONOMIA MISTA | I7: S.A. | J7: FECHADO | K7: NÃO | L7: NÃO | M7: DEPENDENTE | N7: 13 | O7: =IF(AND(F7="ATIVA",VALUE(N7)=0),"VERIFICAR","OK") -> OK | P7: SIM | Q7: SIM | R7: NÃO | T7: 1521027 | U7: 1483227 | V7: =IF(AND(VALUE(N7)=0,VALUE(U7)>0),"VERIFICAR","OK") -> OK | W7: 1483227 | X7: 0 | Y7: NÃO | Z7: 233705.73 | AA7: 0 | AB7: 0 | AC7: -24631.91 | AD7: =IF(AND(Y7="SIM",VALUE(AC7)<0),"VERIFICAR","OK") -> OK | AE7: 3.0056081e+09 | AF7: 0 | AG7: 0 | AH7: 957768.34 | AI7: 1521027 | AJ7: =IF(AND(M7="NÃO DEPENDENTE",VALUE(AI7)>0),"INDÍCIO DE DEPENDÊNCIA POR SUBVENÇÃO","OK") -> OK | AK7: 973545.94 | AL7: 1483227 | AM7: 2447100 | AN7: 2400000 | AO7: 3003209100 | AP7: 3005609100 | AQ7: =AP7-AO7 -> 2400000 | AR7: 3003209100 | AS7: 3005609100 | AT7: 3397100 | AU7: 997100 | AV7: =(AS7-AR7)+(AU7) -> 3397100 | AW7: =IF(OR(VALUE(AQ7)>0,VALUE(AV7)>0),"SIM","NÃO") -> SIM | AX7: =IF(AND(M7="NÃO DEPENDENTE",VALUE(AN7)>0),"VER CAPITAL","OK") -> OK | AY7: =IF(AND(AX7="VER CAPITAL",AW7="NÃO"),"INDÍCIO DE DEPENDÊNCIA POR CAPITAL","OK") -> OK | AZ7: =AC7*100/AE7 -> -0.00081953166
B8: AC | C8: Companhia Industrial de Laticínios do Acre - CILA | D8: CILA | E8: 04.061.693/0001-83 | F8: ATIVA | G8: ABASTECIMENTO DE ALIMENTOS E OUTROS INSUMOS | H8: EMPRESA PÚBLICA | I8: S.A. | J8: FECHADO | K8: NÃO | L8: SIM | M8: DEPENDENTE | N8: 29 | O8: =IF(AND(F8="ATIVA",VALUE(N8)=0),"VERIFICAR","OK") -> OK | P8: SIM | Q8: SIM | R8: NÃO | T8: 2820871.2 | U8: 2497093.8 | V8: =IF(AND(VALUE(N8)=0,VALUE(U8)>0),"VERIFICAR","OK") -> OK | W8: 2820871.2 | X8: 1686.87 | Y8: NÃO | Z8: 2183003.7 | AA8: 0 | AB8: 0 | AC8: 142443.37 | AD8: =IF(AND(Y8="SIM",VALUE(AC8)<0),"VERIFICAR","OK") -> OK | AE8: -88773663 | AF8: 0 | AG8: 0 | AH8: 2317412.3 | AI8: 2820871.2 | AJ8: =IF(AND(M8="NÃO DEPENDENTE",VALUE(AI8)>0),"INDÍCIO DE DEPENDÊNCIA POR SUBVENÇÃO","OK") -> OK | AK8: 2147999.3 | AL8: 1996951.8 | AM8: 0 | AN8: 0 | AO8: 0 | AP8: 0 | AQ8: =AP8-AO8 -> 0 | AR8: 416.44 | AS8: 416.44 | AT8: 0 | AU8: 0 | AV8: =(AS8-AR8)+(AU8) -> 0 | AW8: =IF(OR(VALUE(AQ8)>0,VALUE(AV8)>0),"SIM","NÃO") -> NÃO | AX8: =IF(AND(M8="NÃO DEPENDENTE",VALUE(AN8)>0),"VER CAPITAL","OK") -> OK | AY8: =IF(AND(AX8="VER CAPITAL",AW8="NÃO"),"INDÍCIO DE DEPENDÊNCIA POR CAPITAL","OK") -> OK | AZ8: =AC8*100/AE8 -> -0.16045679
B9: AC | C9: Companhia de Desenvolvimento Industrial do Acre - CODISACRE | D9: CODISACRE | E9: 04.039.277/0001-89 | F9: ATIVA | G9: DESENVOLVIMENTO REGIONAL | H9: EMPRESA PÚBLICA | I9: OUTRAS | J9: FECHADO | K9: NÃO | L9: SIM | M9: DEPENDENTE | N9: 37 | O9: =IF(AND(F9="ATIVA",VALUE(N9)=0),"VERIFICAR","OK") -> OK | P9: SIM | Q9: SIM | R9: NÃO | T9: 5026604.3 | U9: 3944525.1 | V9: =IF(AND(VALUE(N9)=0,VALUE(U9)>0),"VERIFICAR","OK") -> OK | W9: 5010921 | X9: 244185.81 | Y9: NÃO | Z9: 198405.6 | AA9: 0 | AB9: 0 | AC9: 693377.74 | AD9: =IF(AND(Y9="SIM",VALUE(AC9)<0),"VERIFICAR","OK") -> OK | AE9: 6665321.6 | AF9: 0 | AG9: 0 | AH9: 4779201.4 | AI9: 5010921 | AJ9: =IF(AND(M9="NÃO DEPENDENTE",VALUE(AI9)>0),"INDÍCIO DE DEPENDÊNCIA POR SUBVENÇÃO","OK") -> OK | AK9: 410259.38 | AL9: 397316.62 | AM9: 0 | AN9: 0 | AO9: 0 | AP9: 0 | AQ9: =AP9-AO9 -> 0 | AR9: 3791691 | AS9: 3791691 | AT9: 0 | AU9: 0 | AV9: =(AS9-AR9)+(AU9) -> 0 | AW9: =IF(OR(VALUE(AQ9)>0,VALUE(AV9)>0),"SIM","NÃO") -> NÃO | AX9: =IF(AND(M9="NÃO DEPENDENTE",VALUE(AN9)>0),"VER CAPITAL","OK") -> OK | AY9: =IF(AND(AX9="VER CAPITAL",AW9="NÃO"),"INDÍCIO DE DEPENDÊNCIA POR CAPITAL","OK") -> OK | AZ9: =AC9*100/AE9 -> 10.402765
B10: AC | C10: Companhia de Habitação do Acre - COHAB/ACRE | D10: COHAB | E10: 04.066.007/0001-67 | F10: ATIVA | G10: HABITAÇÃO E URBANIZAÇÃO | H10: SOCIEDADE DE ECONOMIA MISTA | I10: OUTRAS | J10: FECHADO | K10: NÃO | L10: NÃO | M10: DEPENDENTE | N10: 63 | O10: =IF(AND(F10="ATIVA",VALUE(N10)=0),"VERIFICAR","OK") -> OK | P10: SIM | Q10: SIM | R10: NÃO | T10: 7431327.1 | U10: 6325167.2 | V10: =IF(AND(VALUE(N10)=0,VALUE(U10)>0),"VERIFICAR","OK") -> OK | W10: 9499084.6 | X10: 0 | Y10: NÃO | Z10: 270124.92 | AA10: 0 | AB10: 0 | AC10: 3953141.1 | AD10: =IF(AND(Y10="SIM",VALUE(AC10)<0),"VERIFICAR","OK") -> OK | AE10: 79307669 | AF10: 0 | AG10: 0 | AH10: 6949505.2 | AI10: 8771679.9 | AJ10: =IF(AND(M10="NÃO DEPENDENTE",VALUE(AI10)>0),"INDÍCIO DE DEPENDÊNCIA POR SUBVENÇÃO","OK") -> OK | AK10: 8064674.4 | AL10: 7204783.3 | AM10: 0 | AN10: 0 | AO10: 0.99 | AP10: 0.99 | AQ10: =AP10-AO10 -> 0 | AR10: 62840607 | AS10: 62840607 | AT10: 0 | AU10: 0 | AV10: =(AS10-AR10)+(AU10) -> 0 | AW10: =IF(OR(VALUE(AQ10)>0,VALUE(AV10)>0),"SIM","NÃO") -> NÃO | AX10: =IF(AND(M10="NÃO DEPENDENTE",VALUE(AN10)>0),"VER CAPITAL","OK") -> OK | AY10: =IF(AND(AX10="VER CAPITAL",AW10="NÃO"),"INDÍCIO DE DEPENDÊNCIA POR CAPITAL","OK") -> OK | AZ10: =AC10*100/AE10 -> 4.9845635
B11: AC | C11: Companhia de Colonização do Acre - COLONACRE | D11: COLONACRE | E11: 04.039.673/0001-06 | F11: EM LIQUIDAÇÃO | G11: DESENVOLVIMENTO REGIONAL | H11: EMPRESA PÚBLICA | I11: OUTRAS | J11: FECHADO | K11: NÃO | L11: SIM | M11: DEPENDENTE | N11: 17 | O11: =IF(AND(F11="ATIVA",VALUE(N11)=0),"VERIFICAR","OK") -> OK | P11: NÃO | Q11: SIM | R11: NÃO | T11: 1705223.6 | U11: 1658046.4 | V11: =IF(AND(VALUE(N11)=0,VALUE(U11)>0),"VERIFICAR","OK") -> OK | W11: 1658621.4 | X11: 0 | Y11: NÃO | Z11: 1040941.4 | AA11: 0 | AB11: 0 | AC11: 46963.39 | AD11: =IF(AND(Y11="SIM",VALUE(AC11)<0),"VERIFICAR","OK") -> OK | AE11: 5690130.8 | AF11: 0 | AG11: 0 | AH11: 1397964.1 | AI11: 1705223.6 | AJ11: =IF(AND(M11="NÃO DEPENDENTE",VALUE(AI11)>0),"INDÍCIO DE DEPENDÊNCIA POR SUBVENÇÃO","OK") -> OK | AK11: 0 | AL11: 0 | AM11: 0 | AN11: 0 | AO11: 3958917.2 | AP11: 3595917.2 | AQ11: =AP11-AO11 -> -363000 | AR11: 3598917.2 | AS11: 3598917.2 | AT11: 0 | AU11: 0 | AV11: =(AS11-AR11)+(AU11) -> 0 | AW11: =IF(OR(VALUE(AQ11)>0,VALUE(AV11)>0),"SIM","NÃO") -> NÃO | AX11: =IF(AND(M11="NÃO DEPENDENTE",VALUE(AN11)>0),"VER CAPITAL","OK") -> OK | AY11: =IF(AND(AX11="VER CAPITAL",AW11="NÃO"),"INDÍCIO DE DEPENDÊNCIA POR CAPITAL","OK") -> OK | AZ11: =AC11*100/AE11 -> 0.82534816
B12: AC | C12: Empresa de Assistência Técnica e Extensão Rural do Acre - EMATER | D12: EMATER | E12: 04.044.244/0001-27 | F12: ATIVA | G12: PESQUISA E ASSISTÊNCIA TÉCNICA AGROPECUÁRIA | H12: EMPRESA PÚBLICA | I12: OUTRAS | J12: FECHADO | K12: NÃO | L12: NÃO | M12: DEPENDENTE | N12: 152 | O12: =IF(AND(F12="ATIVA",VALUE(N12)=0),"VERIFICAR","OK") -> OK | P12: SIM | Q12: SIM | R12: NÃO | T12: 23737121 | U12: 18707804 | V12: =IF(AND(VALUE(N12)=0,VALUE(U12)>0),"VERIFICAR","OK") -> OK | W12: 22994301 | X12: 0 | Y12: NÃO | Z12: 349852.72 | AA12: 0 | AB12: 5040 | AC12: 167735.68 | AD12: =IF(AND(Y12="SIM",VALUE(AC12)<0),"VERIFICAR","OK") -> OK | AE12: -8249.79 | AF12: 0 | AG12: 0 | AH12: 21676919 | AI12: 23737121 | AJ12: =IF(AND(M12="NÃO DEPENDENTE",VALUE(AI12)>0),"INDÍCIO DE DEPENDÊNCIA POR SUBVENÇÃO","OK") -> OK | AK12: 0 | AL12: 0 | AM12: 2052870.8 | AN12: 2149510.2 | AO12: 0 | AP12: 0 | AQ12: =AP12-AO12 -> 0 | AR12: 0 | AS12: 0 | AT12: 0 | AU12: 0 | AV12: =(AS12-AR12)+(AU12) -> 0 | AW12: =IF(OR(VALUE(AQ12)>0,VALUE(AV12)>0),"SIM","NÃO") -> NÃO | AX12: =IF(AND(M12="NÃO DEPENDENTE",VALUE(AN12)>0),"VER CAPITAL","OK") -> OK | AY12: =IF(AND(AX12="VER CAPITAL",AW12="NÃO"),"INDÍCIO DE DEPENDÊNCIA POR CAPITAL","OK") -> OK | AZ12: =AC12*100/AE12 -> -2033.2115
B13: AC | C13: Companhia de Saneamento do Acre - SANACRE | D13: SANACRE | E13: 04.003.232/0001-54 | F13: ATIVA | G13: SANEAMENTO | H13: SOCIEDADE DE ECONOMIA MISTA | I13: OUTRAS | J13: FECHADO | K13: NÃO | L13: NÃO | M13: DEPENDENTE | N13: 189 | O13: =IF(AND(F13="ATIVA",VALUE(N13)=0),"VERIFICAR","OK") -> OK | P13: SIM | Q13: SIM | R13: NÃO | T13: 0 | U13: 22880993 | V13: =IF(AND(VALUE(N13)=0,VALUE(U13)>0),"VERIFICAR","OK") -> OK | W13: 22972686 | X13: 0 | Y13: NÃO | Z13: 0 | AA13: 0 | AB13: 0 | AC13: 91692.53 | AD13: =IF(AND(Y13="SIM",VALUE(AC13)<0),"VERIFICAR","OK") -> OK | AE13: 19805481 | AF13: 0 | AG13: 0 | AH13: 3364776.2 | AI13: 3547857.4 | AJ13: =IF(AND(M13="NÃO DEPENDENTE",VALUE(AI13)>0),"INDÍCIO DE DEPENDÊNCIA POR SUBVENÇÃO","OK") -> OK | AK13: 0 | AL13: 0 | AM13: 0 | AN13: 0 | AO13: 0 | AP13: 0 | AQ13: =AP13-AO13 -> 0 | AR13: 0 | AS13: 0 | AT13: 0 | AU13: 0 | AV13: =(AS13-AR13)+(AU13) -> 0 | AW13: =IF(OR(VALUE(AQ13)>0,VALUE(AV13)>0),"SIM","NÃO") -> NÃO | AX13: =IF(AND(M13="NÃO DEPENDENTE",VALUE(AN13)>0),"VER CAPITAL","OK") -> OK | AY13: =IF(AND(AX13="VER CAPITAL",AW13="NÃO"),"INDÍCIO DE DEPENDÊNCIA POR CAPITAL","OK") -> OK | AZ13: =AC13*100/AE13 -> 0.46296543
B14: AL | C14: Agência de Fomento de Alagoas - Desenvolve | D14: AFAL | E14: 10.769.660/0001-95 | F14: ATIVA | G14: FINANCEIRO | H14: SOCIEDADE DE ECONOMIA MISTA | I14: S.A. | J14: FECHADO | K14: NÃO | L14: SIM | M14: DEPENDENTE | N14: 57 | O14: =IF(AND(F14="ATIVA",VALUE(N14)=0),"VERIFICAR","OK") -> OK | P14: SIM | Q14: SIM | R14: NÃO | T14: -7615000 | U14: 651000 | V14: =IF(AND(VALUE(N14)=0,VALUE(U14)>0),"VERIFICAR","OK") -> OK | W14: 8475000 | X14: 0 | Y14: NÃO | Z14: 119587 | AA14: 0 | AB14: 0 | AC14: -7444000 | AD14: =IF(AND(Y14="SIM",VALUE(AC14)<0),"VERIFICAR","OK") -> OK | AE14: 45079000 | AG14: 0 | AH14: 0 | AI14: 0 | AJ14: =IF(AND(M14="NÃO DEPENDENTE",VALUE(AI14)>0),"INDÍCIO DE DEPENDÊNCIA POR SUBVENÇÃO","OK") -> OK | AK14: 0 | AL14: 0 | AM14: 0 | AN14: 0 | AO14: 8041 | AP14: 8041 | AQ14: =AP14-AO14 -> 0 | AR14: 80414000 | AS14: 80414000 | AT14: 0 | AU14: 0 | AV14: =(AS14-AR14)+(AU14) -> 0 | AW14: =IF(OR(VALUE(AQ14)>0,VALUE(AV14)>0),"SIM","NÃO") -> NÃO | AX14: =IF(AND(M14="NÃO DEPENDENTE",VALUE(AN14)>0),"VER CAPITAL","OK") -> OK | AY14: =IF(AND(AX14="VER CAPITAL",AW14="NÃO"),"INDÍCIO DE DEPENDÊNCIA POR CAPITAL","OK") -> OK | AZ14: =AC14*100/AE14 -> -16.513232
B15: AL | C15: Alagoas Ativos S.A | D15: ALAtivos | E15: 29.218.037/0001-72 | F15: ATIVA | G15: GESTÃO DE ATIVOS | H15: EMPRESA PÚBLICA | I15: S.A. | J15: FECHADO | K15: NÃO | L15: NÃO | M15: NÃO DEPENDENTE | N15: 19 | O15: =IF(AND(F15="ATIVA",VALUE(N15)=0),"VERIFICAR","OK") -> OK | P15: SIM | Q15: SIM | R15: NÃO | T15: 5313174.6 | U15: 2192507.7 | V15: =IF(AND(VALUE(N15)=0,VALUE(U15)>0),"VERIFICAR","OK") -> OK | W15: 7586434.2 | X15: 0 | Y15: NÃO | Z15: 405711.63 | AA15: 0 | AB15: 0 | AC15: 646243.59 | AD15: =IF(AND(Y15="SIM",VALUE(AC15)<0),"VERIFICAR","OK") -> OK | AE15: 1354881.7 | AG15: 0 | AH15: 0 | AI15: 0 | AJ15: =IF(AND(M15="NÃO DEPENDENTE",VALUE(AI15)>0),"INDÍCIO DE DEPENDÊNCIA POR SUBVENÇÃO","OK") -> OK | AK15: 0 | AL15: 0 | AM15: 0 | AN15: 0 | AO15: 0 | AP15: 0 | AQ15: =AP15-AO15 -> 0 | AR15: 10000000 | AS15: 0 | AT15: 0 | AU15: 0 | AV15: =(AS15-AR15)+(AU15) -> -10000000 | AW15: =IF(OR(VALUE(AQ15)>0,VALUE(AV15)>0),"SIM","NÃO") -> NÃO | AX15: =IF(AND(M15="NÃO DEPENDENTE",VALUE(AN15)>0),"VER CAPITAL","OK") -> OK | AY15: =IF(AND(AX15="VER CAPITAL",AW15="NÃO"),"INDÍCIO DE DEPENDÊNCIA POR CAPITAL","OK") -> OK | AZ15: =AC15*100/AE15 -> 47.697419
B16: AL | C16: Gás de Alagoas S.A | D16: ALGÁS | E16: 69.983.484/0001-32 | F16: ATIVA | G16: GÁS E DERIVADOS | H16: SOCIEDADE DE ECONOMIA MISTA | I16: S.A. | J16: FECHADO | K16: NÃO | L16: NÃO | M16: NÃO DEPENDENTE | N16: 161 | O16: =IF(AND(F16="ATIVA",VALUE(N16)=0),"VERIFICAR","OK") -> OK | P16: SIM | Q16: SIM | R16: SIM | S16: https://governanca,algas,com,br/carta-anual-de-politicas-publicas-e-governanca-corporativa | T16: 4.5279713e+08 | U16: 25539770 | V16: =IF(AND(VALUE(N16)=0,VALUE(U16)>0),"VERIFICAR","OK") -> OK | W16: 4.5719368e+08 | X16: 34430658 | Y16: NÃO | Z16: 398267.27 | AA16: 0 | AB16: 0 | AC16: 40882910 | AD16: =IF(AND(Y16="SIM",VALUE(AC16)<0),"VERIFICAR","OK") -> OK | AE16: 1.4065218e+08 | AG16: 10638724 | AH16: 0 | AI16: 0 | AJ16: =IF(AND(M16="NÃO DEPENDENTE",VALUE(AI16)>0),"INDÍCIO DE DEPENDÊNCIA POR SUBVENÇÃO","OK") -> OK | AK16: 0 | AL16: 0 | AM16: 0 | AN16: 0 | AO16: 2873893 | AP16: 3212493.4 | AQ16: =AP16-AO16 -> 338600.4 | AR16: 23729600 | AS16: 26525400 | AT16: 0 | AU16: 0 | AV16: =(AS16-AR16)+(AU16) -> 2795799.8 | AW16: =IF(OR(VALUE(AQ16)>0,VALUE(AV16)>0),"SIM","NÃO") -> SIM | AX16: =IF(AND(M16="NÃO DEPENDENTE",VALUE(AN16)>0),"VER CAPITAL","OK") -> OK | AY16: =IF(AND(AX16="VER CAPITAL",AW16="NÃO"),"INDÍCIO DE DEPENDÊNCIA POR CAPITAL","OK") -> OK | AZ16: =AC16*100/AE16 -> 29.066674
B17: AL | C17: Companhia Alagoana de Recursos Humanos e Patrimoniais | D17: CARHP | E17: 12.291.274/0001-66 | F17: EM LIQUIDAÇÃO | G17: HABITAÇÃO E URBANIZAÇÃO | H17: SOCIEDADE DE ECONOMIA MISTA | I17: S.A. | J17: FECHADO | K17: NÃO | L17: NÃO | M17: DEPENDENTE | N17: 1 | O17: =IF(AND(F17="ATIVA",VALUE(N17)=0),"VERIFICAR","OK") -> OK | P17: NÃO | Q17: SIM | R17: NÃO | T17: 918583.9 | U17: 16778.87 | V17: =IF(AND(VALUE(N17)=0,VALUE(U17)>0),"VERIFICAR","OK") -> OK | W17: 376826.32 | X17: 323632.27 | Y17: NÃO | Z17: 218125.31 | AA17: 0 | AB17: 0 | AC17: -22558098 | AD17: =IF(AND(Y17="SIM",VALUE(AC17)<0),"VERIFICAR","OK") -> OK | AE17: 19491992 | AG17: 0 | AH17: 5776972.9 | AI17: 2734522 | AJ17: =IF(AND(M17="NÃO DEPENDENTE",VALUE(AI17)>0),"INDÍCIO DE DEPENDÊNCIA POR SUBVENÇÃO","OK") -> OK | AK17: 1.0955497e+08 | AL17: 1.0961923e+08 | AM17: 0 | AN17: 0 | AO17: 0 | AP17: 0 | AQ17: =AP17-AO17 -> 0 | AR17: 20251521 | AS17: 20251521 | AT17: 0 | AU17: 0 | AV17: =(AS17-AR17)+(AU17) -> 0 | AW17: =IF(OR(VALUE(AQ17)>0,VALUE(AV17)>0),"SIM","NÃO") -> NÃO | AX17: =IF(AND(M17="NÃO DEPENDENTE",VALUE(AN17)>0),"VER CAPITAL","OK") -> OK | AY17: =IF(AND(AX17="VER CAPITAL",AW17="NÃO"),"INDÍCIO DE DEPENDÊNCIA POR CAPITAL","OK") -> OK | AZ17: =AC17*100/AE17 -> -115.73008
B18: AL | C18: Companhia de Saneamento de Alagoas | D18: CASAL | E18: 12.294.708/0001-81 | F18: ATIVA | G18: SANEAMENTO | H18: SOCIEDADE DE ECONOMIA MISTA | I18: S.A. | J18: FECHADO | K18: NÃO | L18: NÃO | M18: NÃO DEPENDENTE | N18: 856 | O18: =IF(AND(F18="ATIVA",VALUE(N18)=0),"VERIFICAR","OK") -> OK | P18: SIM | Q18: SIM | R18: SIM | S18: https://www,casal,al,gov,br/arquivos/carta-anual-de-politicas-publicas-e-governanca-corporativa-2024/ | T18: 464911233 | U18: 109360615 | V18: =IF(AND(VALUE(N18)=0,VALUE(U18)>0),"VERIFICAR","OK") -> OK | W18: 5.4383181e+08 | X18: 11453707 | Y18: NÃO | Z18: 475077.99 | AA18: 0 | AB18: 23628.57 | AC18: 76660074 | AD18: =IF(AND(Y18="SIM",VALUE(AC18)<0),"VERIFICAR","OK") -> OK | AE18: 6571826958 | AG18: 0 | AH18: 0 | AI18: 0 | AJ18: =IF(AND(M18="NÃO DEPENDENTE",VALUE(AI18)>0),"INDÍCIO DE DEPENDÊNCIA POR SUBVENÇÃO","OK") -> OK | AK18: 0 | AL18: 0 | AM18: 44880272 | AN18: 51271902 | AO18: 1.364436e+09 | AP18: 1.364436e+09 | AQ18: =AP18-AO18 -> 0 | AR18: 4.6968194e+08 | AS18: 5.2557004e+08 | AT18: 2.8769973e+08 | AU18: 2.3181163e+08 | AV18: =(AS18-AR18)+(AU18) -> 2.8769973e+08 | AW18: =IF(OR(VALUE(AQ18)>0,VALUE(AV18)>0),"SIM","NÃO") -> SIM | AX18: =IF(AND(M18="NÃO DEPENDENTE",VALUE(AN18)>0),"VER CAPITAL","OK") -> VER CAPITAL | AY18: =IF(AND(AX18="VER CAPITAL",AW18="NÃO"),"INDÍCIO DE DEPENDÊNCIA POR CAPITAL","OK") -> OK | AZ18: =AC18*100/AE18 -> 1.1664956
B19: AL | C19: Companhia de Edição Impressão e Publicação de Alagoas | D19: CEPAL | E19: 04.308.836/0001-09 | F19: ATIVA | G19: COMUNICAÇÃO | H19: SOCIEDADE DE ECONOMIA MISTA | I19: S.A. | J19: FECHADO | K19: NÃO | L19: NÃO | M19: NÃO DEPENDENTE | N19: 119 | O19: =IF(AND(F19="ATIVA",VALUE(N19)=0),"VERIFICAR","OK") -> OK | P19: SIM | Q19: SIM | R19: NÃO | S19: https://www,imprensaoficial,al,gov,br/storage/files/2025/04/Carta_Anual_de_Políticas_Públicas_CEPAL_Aprovada_Conselho_2024,pdf | T19: 17985778 | U19: 12885086 | V19: =IF(AND(VALUE(N19)=0,VALUE(U19)>0),"VERIFICAR","OK") -> OK | W19: 20957137 | X19: 0 | Y19: NÃO | Z19: 298779.51 | AA19: 0 | AB19: 0 | AC19: -5899240.4 | AD19: =IF(AND(Y19="SIM",VALUE(AC19)<0),"VERIFICAR","OK") -> OK | AE19: 217370.56 | AG19: 0 | AH19: 0 | AI19: 0 | AJ19: =IF(AND(M19="NÃO DEPENDENTE",VALUE(AI19)>0),"INDÍCIO DE DEPENDÊNCIA POR SUBVENÇÃO","OK") -> OK | AK19: 0 | AL19: 0 | AM19: 0 | AN19: 0 | AO19: 10083000 | AP19: 10083000 | AQ19: =AP19-AO19 -> 0 | AR19: 10083000 | AS19: 10083000 | AT19: 0 | AU19: 0 | AV19: =(AS19-AR19)+(AU19) -> 0 | AW19: =IF(OR(VALUE(AQ19)>0,VALUE(AV19)>0),"SIM","NÃO") -> NÃO | AX19: =IF(AND(M19="NÃO DEPENDENTE",VALUE(AN19)>0),"VER CAPITAL","OK") -> OK | AY19: =IF(AND(AX19="VER CAPITAL",AW19="NÃO"),"INDÍCIO DE DEPENDÊNCIA POR CAPITAL","OK") -> OK | AZ19: =AC19*100/AE19 -> -2713.9096
B20: AL | C20: Laboratório Industrial Farmacêutico | D20: LIFAL | E20: 12.343.158/0001-43 | F20: EM LIQUIDAÇÃO | G20: SAÚDE | H20: SOCIEDADE DE ECONOMIA MISTA | I20: S.A. | J20: FECHADO | K20: NÃO | L20: NÃO | M20: DEPENDENTE | N20: 0 | O20: =IF(AND(F20="ATIVA",VALUE(N20)=0),"VERIFICAR","OK") -> OK | P20: NÃO | Q20: SIM | R20: NÃO | T20: 416573.91 | U20: 4793.94 | V20: =IF(AND(VALUE(N20)=0,VALUE(U20)>0),"VERIFICAR","OK") -> VERIFICAR | W20: 4793.94 | X20: 0 | Y20: NÃO | Z20: 62321.22 | AA20: 0 | AB20: 152320.29 | AC20: 86544.66 | AD20: =IF(AND(Y20="SIM",VALUE(AC20)<0),"VERIFICAR","OK") -> OK | AE20: -50970.82 | AG20: 0 | AH20: 354932.54 | AI20: 430375.27 | AJ20: =IF(AND(M20="NÃO DEPENDENTE",VALUE(AI20)>0),"INDÍCIO DE DEPENDÊNCIA POR SUBVENÇÃO","OK") -> OK | AK20: 837615.8 | AL20: 837615.8 | AM20: 0 | AN20: 0 | AO20: 0 | AP20: 0 | AQ20: =AP20-AO20 -> 0 | AR20: 0 | AS20: 0 | AT20: 0 | AU20: 0 | AV20: =(AS20-AR20)+(AU20) -> 0 | AW20: =IF(OR(VALUE(AQ20)>0,VALUE(AV20)>0),"SIM","NÃO") -> NÃO | AX20: =IF(AND(M20="NÃO DEPENDENTE",VALUE(AN20)>0),"VER CAPITAL","OK") -> OK | AY20: =IF(AND(AX20="VER CAPITAL",AW20="NÃO"),"INDÍCIO DE DEPENDÊNCIA POR CAPITAL","OK") -> OK | AZ20: =AC20*100/AE20 -> -169.79256
B21: AL | C21: Banco do Estado de Alagoas S.A | D21: PRODUBAN | E21: 12.275.749/0001-20 | F21: EM LIQUIDAÇÃO | G21: FINANCEIRO | H21: SOCIEDADE DE ECONOMIA MISTA | I21: S.A. | J21: FECHADO | K21: NÃO | L21: NÃO | M21: DEPENDENTE | N21: 3 | O21: =IF(AND(F21="ATIVA",VALUE(N21)=0),"VERIFICAR","OK") -> OK | P21: NÃO | Q21: SIM | R21: NÃO | T21: 538686.32 | U21: 554179.85 | V21: =IF(AND(VALUE(N21)=0,VALUE(U21)>0),"VERIFICAR","OK") -> OK | W21: 20349597 | X21: 0 | Y21: NÃO | Z21: 325324.89 | AA21: 0 | AB21: 0 | AC21: -20349597 | AD21: =IF(AND(Y21="SIM",VALUE(AC21)<0),"VERIFICAR","OK") -> OK | AE21: 1.2073279e+08 | AG21: 0 | AH21: 100000 | AI21: 100000 | AJ21: =IF(AND(M21="NÃO DEPENDENTE",VALUE(AI21)>0),"INDÍCIO DE DEPENDÊNCIA POR SUBVENÇÃO","OK") -> OK | AK21: 0 | AL21: 0 | AM21: 0 | AN21: 16000000 | AO21: 6750 | AP21: 6750 | AQ21: =AP21-AO21 -> 0 | AR21: 4.998111e+08 | AS21: 4.998111e+08 | AT21: 0 | AU21: 0 | AV21: =(AS21-AR21)+(AU21) -> 0 | AW21: =IF(OR(VALUE(AQ21)>0,VALUE(AV21)>0),"SIM","NÃO") -> NÃO | AX21: =IF(AND(M21="NÃO DEPENDENTE",VALUE(AN21)>0),"VER CAPITAL","OK") -> OK | AY21: =IF(AND(AX21="VER CAPITAL",AW21="NÃO"),"INDÍCIO DE DEPENDÊNCIA POR CAPITAL","OK") -> OK | AZ21: =AC21*100/AE21 -> -16.855071
B22: AL | C22: Serviços de Engenharia de Alagoas S.A | D22: SERVEAL | E22: 12.318.887/0001-40 | F22: EM LIQUIDAÇÃO | G22: OUTROS | H22: SOCIEDADE DE ECONOMIA MISTA | I22: S.A. | J22: FECHADO | K22: NÃO | L22: NÃO | M22: DEPENDENTE | N22: 5 | O22: =IF(AND(F22="ATIVA",VALUE(N22)=0),"VERIFICAR","OK") -> OK | P22: NÃO | Q22: SIM | R22: NÃO | T22: 539804.76 | U22: 41523.44 | V22: =IF(AND(VALUE(N22)=0,VALUE(U22)>0),"VERIFICAR","OK") -> OK | W22: 42358.91 | X22: 0 | Y22: NÃO | Z22: 539804.72 | AA22: 0 | AB22: 0 | AC22: 0 | AD22: =IF(AND(Y22="SIM",VALUE(AC22)<0),"VERIFICAR","OK") -> OK | AE22: -1653049.8 | AG22: 0 | AH22: 1018063.9 | AI22: 387314.54 | AJ22: =IF(AND(M22="NÃO DEPENDENTE",VALUE(AI22)>0),"INDÍCIO DE DEPENDÊNCIA POR SUBVENÇÃO","OK") -> OK | AK22: 3889423.1 | AL22: 3855251.4 | AM22: 0 | AN22: 0 | AO22: 0 | AP22: 0 | AQ22: =AP22-AO22 -> 0 | AR22: -505486.95 | AS22: -505486.95 | AT22: 0 | AU22: 0 | AV22: =(AS22-AR22)+(AU22) -> 0 | AW22: =IF(OR(VALUE(AQ22)>0,VALUE(AV22)>0),"SIM","NÃO") -> NÃO | AX22: =IF(AND(M22="NÃO DEPENDENTE",VALUE(AN22)>0),"VER CAPITAL","OK") -> OK | AY22: =IF(AND(AX22="VER CAPITAL",AW22="NÃO"),"INDÍCIO DE DEPENDÊNCIA POR CAPITAL","OK") -> OK | AZ22: =AC22*100/AE22 -> 0
B23: AM | C23: Agência de Desenvolvimento Sustentável do Amazonas | D23: ADS | E23: 05.867.581/0001-87 | F23: ATIVA | G23: DESENVOLVIMENTO REGIONAL | H23: EMPRESA PÚBLICA | I23: S.A. | J23: FECHADO | K23: NÃO | L23: NÃO | M23: DEPENDENTE | N23: 83 | O23: =IF(AND(F23="ATIVA",VALUE(N23)=0),"VERIFICAR","OK") -> OK | P23: SIM | Q23: SIM | R23: NÃO | S23: Não possui | T23: 1890024 | U23: 4164370.4 | V23: =IF(AND(VALUE(N23)=0,VALUE(U23)>0),"VERIFICAR","OK") -> OK | W23: 1.3566569e+08 | X23: 0 | Y23: NÃO | Z23: 180416.58 | AA23: 0 | AB23: 133966.4 | AC23: -4743532 | AD23: =IF(AND(Y23="SIM",VALUE(AC23)<0),"VERIFICAR","OK") -> OK | AE23: 795178.7 | AF23: 0 | AG23: 0 | AH23: 1.0214802e+08 | AI23: 1.2582989e+08 | AJ23: =IF(AND(M23="NÃO DEPENDENTE",VALUE(AI23)>0),"INDÍCIO DE DEPENDÊNCIA POR SUBVENÇÃO","OK") -> OK | AK23: 0 | AL23: 0 | AM23: 0 | AN23: 0 | AO23: 0 | AP23: 0 | AQ23: =AP23-AO23 -> 0 | AR23: 10000000 | AS23: 10000000 | AT23: 0 | AU23: 0 | AV23: =(AS23-AR23)+(AU23) -> 0 | AW23: =IF(OR(VALUE(AQ23)>0,VALUE(AV23)>0),"SIM","NÃO") -> NÃO | AX23: =IF(AND(M23="NÃO DEPENDENTE",VALUE(AN23)>0),"VER CAPITAL","OK") -> OK | AY23: =IF(AND(AX23="VER CAPITAL",AW23="NÃO"),"INDÍCIO DE DEPENDÊNCIA POR CAPITAL","OK") -> OK | AZ23: =AC23*100/AE23 -> -596.5366
B24: AM | C24: Agência de Fomento do Estado do Amazonas | D24: AFEAM | E24: 03.183.937/0001-38 | F24: ATIVA | G24: FINANCEIRO | H24: EMPRESA PÚBLICA | I24: S.A. | J24: FECHADO | K24: NÃO | L24: NÃO | M24: NÃO DEPENDENTE | N24: 253 | O24: =IF(AND(F24="ATIVA",VALUE(N24)=0),"VERIFICAR","OK") -> OK | P24: SIM | Q24: SIM | R24: SIM | S24: https://www,afeam,am,gov,br/wpcontent/ uploads/2025/04/CARTAANUAL¿ 2024,pdf | T24: 26835089 | U24: 50347133 | V24: =IF(AND(VALUE(N24)=0,VALUE(U24)>0),"VERIFICAR","OK") -> OK | W24: 3.723726e+08 | X24: 3.2202546e+08 | Y24: NÃO | Z24: 567085.72 | AA24: 0 | AB24: 34305.43 | AC24: 14463130 | AD24: =IF(AND(Y24="SIM",VALUE(AC24)<0),"VERIFICAR","OK") -> OK | AE24: 1.2578599e+08 | AF24: 0 | AG24: 0 | AH24: 0 | AI24: 0 | AJ24: =IF(AND(M24="NÃO DEPENDENTE",VALUE(AI24)>0),"INDÍCIO DE DEPENDÊNCIA POR SUBVENÇÃO","OK") -> OK | AK24: 0 | AL24: 0 | AM24: 0 | AN24: 0 | AO24: 103963256 | AP24: 106465046 | AQ24: =AP24-AO24 -> 2501790 | AR24: 103963256 | AS24: 106465046 | AT24: 0 | AU24: 0 | AV24: =(AS24-AR24)+(AU24) -> 2501790 | AW24: =IF(OR(VALUE(AQ24)>0,VALUE(AV24)>0),"SIM","NÃO") -> SIM | AX24: =IF(AND(M24="NÃO DEPENDENTE",VALUE(AN24)>0),"VER CAPITAL","OK") -> OK | AY24: =IF(AND(AX24="VER CAPITAL",AW24="NÃO"),"INDÍCIO DE DEPENDÊNCIA POR CAPITAL","OK") -> OK | AZ24: =AC24*100/AE24 -> 11.498204
B25: AM | C25: Empresa Estadual de Turismo | D25: AMAZONASTUR | E25: 05.662.046/0001-90 | F25: ATIVA | G25: TURISMO | H25: EMPRESA PÚBLICA | I25: OUTRAS | J25: FECHADO | K25: NÃO | L25: NÃO | M25: DEPENDENTE | N25: 144 | O25: =IF(AND(F25="ATIVA",VALUE(N25)=0),"VERIFICAR","OK") -> OK | P25: SIM | Q25: SIM | R25: SIM | S25: https://www,amazonastur,am,gov,br/wpcontent/ uploads/2024/10/amazonastur-cartaservicos- 2024,pdf | T25: 631607.64 | U25: 13648435 | V25: =IF(AND(VALUE(N25)=0,VALUE(U25)>0),"VERIFICAR","OK") -> OK | W25: 1.0485808e+08 | X25: 38772283 | Y25: NÃO | Z25: 407740 | AA25: 0 | AB25: 0 | AC25: -803617.85 | AD25: =IF(AND(Y25="SIM",VALUE(AC25)<0),"VERIFICAR","OK") -> OK | AE25: 4189166.1 | AF25: 0 | AG25: 0 | AH25: 71978546 | AI25: 1.0425863e+08 | AJ25: =IF(AND(M25="NÃO DEPENDENTE",VALUE(AI25)>0),"INDÍCIO DE DEPENDÊNCIA POR SUBVENÇÃO","OK") -> OK | AK25: 2807045.4 | AL25: 6734566.2 | AM25: 0 | AN25: 0 | AO25: 1 | AP25: 1 | AQ25: =AP25-AO25 -> 0 | AR25: 27123375 | AS25: 27123375 | AT25: 0 | AU25: 0 | AV25: =(AS25-AR25)+(AU25) -> 0 | AW25: =IF(OR(VALUE(AQ25)>0,VALUE(AV25)>0),"SIM","NÃO") -> NÃO | AX25: =IF(AND(M25="NÃO DEPENDENTE",VALUE(AN25)>0),"VER CAPITAL","OK") -> OK | AY25: =IF(AND(AX25="VER CAPITAL",AW25="NÃO"),"INDÍCIO DE DEPENDÊNCIA POR CAPITAL","OK") -> OK | AZ25: =AC25*100/AE25 -> -19.183242
